Workbook

Sheet Table 2
B2: Countries | C2: Foreign Equity in Portfolio % | F2: Equity Home bias | I2: Foreign debt in Portfolio % | K2: Debt Home bias
C3: 1993 | D3: 2003 | E3: 2022 | F3: 1993 | G3: 2003 | H3: 2022 | I3: 1993 | J3: 2003 | K3: 1993 | L3: 2003
B4: Australia | C4: =('Portfolio equity assets '!B3)/('Portfolio equity assets '!B3+('Market Cap'!B3/1000000)-'Portfolio equity liabilities '!B3)*100 -> 11.325419 | D4: =('Portfolio equity assets '!L3)/('Portfolio equity assets '!L3+('Market Cap'!L3/1000000)-'Portfolio equity liabilities '!L3)*100 -> 17.227788 | E4: =('Portfolio equity assets '!AE3)/('Portfolio equity assets '!AE3+('Market Cap'!AE3/1000000)-'Portfolio equity liabilities '!AE3)*100 -> 39.439377 | F4: =(100-C4)/100 -> 0.88674581 | G4: =(100-D4)/100 -> 0.82772212 | H4: =(100-E4)/100 -> 0.60560623 | I4: =('Portfolio debt assets '!B3)/(('Portfolio debt assets '!B3+('Domestic debt'!B3*1000)))*100 -> 15.322858 | J4: =('Portfolio debt assets '!L3)/(('Portfolio debt assets '!L3+('Domestic debt'!L3*1000)))*100 -> 21.710532 | K4: =(100-I4)/100 -> 0.84677142 | L4: =(100-J4)/100 -> 0.78289468
B5: Austria | C5: =('Portfolio equity assets '!B4)/('Portfolio equity assets '!B4+('Market Cap'!B4/1000000)-'Portfolio equity liabilities '!B4)*100 -> 14.115748 | D5: =('Portfolio equity assets '!L4)/('Portfolio equity assets '!L4+('Market Cap'!L4/1000000)-'Portfolio equity liabilities '!L4)*100 -> 59.499867 | E5: =('Portfolio equity assets '!AE4)/('Portfolio equity assets '!AE4+('Market Cap'!AE4/1000000)-'Portfolio equity liabilities '!AE4)*100 -> 76.521173 | F5: =(100-C5)/100 -> 0.85884252 | G5: =(100-D5)/100 -> 0.40500133 | H5: =(100-E5)/100 -> 0.23478827 | I5: =('Portfolio debt assets '!B4)/(('Portfolio debt assets '!B4+('Domestic debt'!B4*1000)))*100 -> 47.238975 | J5: =('Portfolio debt assets '!L4)/(('Portfolio debt assets '!L4+('Domestic debt'!L4*1000)))*100 -> 61.67718 | K5: =(100-I5)/100 -> 0.52761025 | L5: =(100-J5)/100 -> 0.3832282
B6: Belgium | C6: =('Portfolio equity assets '!B5)/('Portfolio equity assets '!B5+('Market Cap'!B5/1000000)-'Portfolio equity liabilities '!B5)*100 -> 45.968589 | D6: =('Portfolio equity assets '!L5)/('Portfolio equity assets '!L5+('Market Cap'!L5/1000000)-'Portfolio equity liabilities '!L5)*100 -> 50.16678 | E6: -- | F6: =(100-C6)/100 -> 0.54031411 | G6: =(100-D6)/100 -> 0.4983322 | H6: -- | I6: =('Portfolio debt assets '!B5)/(('Portfolio debt assets '!B5+('Domestic debt'!B5*1000)))*100 -> 51.112668 | J6: =('Portfolio debt assets '!L5)/(('Portfolio debt assets '!L5+('Domestic debt'!L5*1000)))*100 -> 66.937013 | K6: =(100-I6)/100 -> 0.48887332 | L6: =(100-J6)/100 -> 0.33062987
B7: Canada | C7: =('Portfolio equity assets '!B6)/('Portfolio equity assets '!B6+('Market Cap'!B6/1000000)-'Portfolio equity liabilities '!B6)*100 -> 11.164614 | D7: =('Portfolio equity assets '!L6)/('Portfolio equity assets '!L6+('Market Cap'!L6/1000000)-'Portfolio equity liabilities '!L6)*100 -> 27.214908 | E7: =('Portfolio equity assets '!AE6)/('Portfolio equity assets '!AE6+('Market Cap'!AE6/1000000)-'Portfolio equity liabilities '!AE6)*100 -> 43.50758 | F7: =(100-C7)/100 -> 0.88835386 | G7: =(100-D7)/100 -> 0.72785092 | H7: =(100-E7)/100 -> 0.5649242 | I7: =('Portfolio debt assets '!B6)/(('Portfolio debt assets '!B6+('Domestic debt'!B6*1000)))*100 -> 15.66043 | J7: =('Portfolio debt assets '!L6)/(('Portfolio debt assets '!L6+('Domestic debt'!L6*1000)))*100 -> 19.246233 | K7: =(100-I7)/100 -> 0.8433957 | L7: =(100-J7)/100 -> 0.80753767
B8: Denmark | C8: =('Portfolio equity assets '!B7)/('Portfolio equity assets '!B7+('Market Cap'!B7/1000000)-'Portfolio equity liabilities '!B7)*100 -> 17.854257 | D8: =('Portfolio equity assets '!L7)/('Portfolio equity assets '!L7+('Market Cap'!L7/1000000)-'Portfolio equity liabilities '!L7)*100 -> 36.573675 | E8: -- | F8: =(100-C8)/100 -> 0.82145743 | G8: =(100-D8)/100 -> 0.63426325 | H8: -- | I8: =('Portfolio debt assets '!B7)/(('Portfolio debt assets '!B7+('Domestic debt'!B7*1000)))*100 -> 25.192205 | J8: =('Portfolio debt assets '!L7)/(('Portfolio debt assets '!L7+('Domestic debt'!L7*1000)))*100 -> 29.274941 | K8: =(100-I8)/100 -> 0.74807795 | L8: =(100-J8)/100 -> 0.70725059
B9: Finland | C9: =('Portfolio equity assets '!B8)/('Portfolio equity assets '!B8+('Market Cap'!B8/1000000)-'Portfolio equity liabilities '!B8)*100 -> 1.658819 | D9: =('Portfolio equity assets '!L8)/('Portfolio equity assets '!L8+('Market Cap'!L8/1000000)-'Portfolio equity liabilities '!L8)*100 -> -74.441854 | E9: -- | F9: =(100-C9)/100 -> 0.98341181 | G9: -- | H9: -- | I9: =('Portfolio debt assets '!B8)/(('Portfolio debt assets '!B8+('Domestic debt'!B8*1000)))*100 -> 29.323103 | J9: =('Portfolio debt assets '!L8)/(('Portfolio debt assets '!L8+('Domestic debt'!L8*1000)))*100 -> 66.82765 | K9: =(100-I9)/100 -> 0.70676897 | L9: =(100-J9)/100 -> 0.3317235
B10: France | C10: =('Portfolio equity assets '!B9)/('Portfolio equity assets '!B9+('Market Cap'!B9/1000000)-'Portfolio equity liabilities '!B9)*100 -> 12.858276 | D10: =('Portfolio equity assets '!L9)/('Portfolio equity assets '!L9+('Market Cap'!L9/1000000)-'Portfolio equity liabilities '!L9)*100 -> 28.229525 | E10: -- | F10: =(100-C10)/100 -> 0.87141724 | G10: =(100-D10)/100 -> 0.71770475 | H10: -- | I10: =('Portfolio debt assets '!B9)/(('Portfolio debt assets '!B9+('Domestic debt'!B9*1000)))*100 -> 39.232456 | J10: =('Portfolio debt assets '!L9)/(('Portfolio debt assets '!L9+('Domestic debt'!L9*1000)))*100 -> 51.973598 | K10: =(100-I10)/100 -> 0.60767544 | L10: =(100-J10)/100 -> 0.48026402
B11: Germany | C11: =('Portfolio equity assets '!B10)/('Portfolio equity assets '!B10+('Market Cap'!B10/1000000)-'Portfolio equity liabilities '!B10)*100 -> 24.866332 | D11: =('Portfolio equity assets '!L10)/('Portfolio equity assets '!L10+('Market Cap'!L10/1000000)-'Portfolio equity liabilities '!L10)*100 -> 44.572407 | E11: =('Portfolio equity assets '!AE10)/('Portfolio equity assets '!AE10+('Market Cap'!AE10/1000000)-'Portfolio equity liabilities '!AE10)*100 -> 69.307703 | F11: =(100-C11)/100 -> 0.75133668 | G11: =(100-D11)/100 -> 0.55427593 | H11: =(100-E11)/100 -> 0.30692297 | I11: =('Portfolio debt assets '!B10)/(('Portfolio debt assets '!B10+('Domestic debt'!B10*1000)))*100 -> 40.569591 | J11: =('Portfolio debt assets '!L10)/(('Portfolio debt assets '!L10+('Domestic debt'!L10*1000)))*100 -> 56.05436 | K11: =(100-I11)/100 -> 0.59430409 | L11: =(100-J11)/100 -> 0.4394564
B12: Greece | C12: -- | D12: =('Portfolio equity assets '!L11)/('Portfolio equity assets '!L11+('Market Cap'!L11/1000000)-'Portfolio equity liabilities '!L11)*100 -> 4.6226053 | E12: =('Portfolio equity assets '!AE11)/('Portfolio equity assets '!AE11+('Market Cap'!AE11/1000000)-'Portfolio equity liabilities '!AE11)*100 -> 26.915608 | F12: -- | G12: =(100-D12)/100 -> 0.95377395 | H12: =(100-E12)/100 -> 0.73084392 | I12: =('Portfolio debt assets '!B11)/(('Portfolio debt assets '!B11+('Domestic debt'!B11*1000)))*100 -> 23.868399 | J12: =('Portfolio debt assets '!L11)/(('Portfolio debt assets '!L11+('Domestic debt'!L11*1000)))*100 -> 41.015365 | K12: =(100-I12)/100 -> 0.76131601 | L12: =(100-J12)/100 -> 0.58984635
B13: Iceland | C13: -- | D13: -- | E13: -- | F13: -- | G13: -- | H13: -- | I13: =('Portfolio debt assets '!B12)/(('Portfolio debt assets '!B12+('Domestic debt'!B12*1000)))*100 -> 8.4090169 | J13: =('Portfolio debt assets '!L12)/(('Portfolio debt assets '!L12+('Domestic debt'!L12*1000)))*100 -> 20.900357 | K13: =(100-I13)/100 -> 0.91590983 | L13: =(100-J13)/100 -> 0.79099643
B14: Ireland | C14: -- | D14: -- | E14: -- | F14: -- | G14: -- | H14: -- | I14: =('Portfolio debt assets '!B13)/(('Portfolio debt assets '!B13+('Domestic debt'!B13*1000)))*100 -> 63.487979 | J14: =('Portfolio debt assets '!L13)/(('Portfolio debt assets '!L13+('Domestic debt'!L13*1000)))*100 -> 90.019032 | K14: =(100-I14)/100 -> 0.36512021 | L14: =(100-J14)/100 -> 0.099809676
B15: Italy | C15: =('Portfolio equity assets '!B14)/('Portfolio equity assets '!B14+('Market Cap'!B14/1000000)-'Portfolio equity liabilities '!B14)*100 -> 22.066123 | D15: =('Portfolio equity assets '!L14)/('Portfolio equity assets '!L14+('Market Cap'!L14/1000000)-'Portfolio equity liabilities '!L14)*100 -> 45.702407 | E15: -- | F15: =(100-C15)/100 -> 0.77933877 | G15: =(100-D15)/100 -> 0.54297593 | H15: -- | I15: =('Portfolio debt assets '!B14)/(('Portfolio debt assets '!B14+('Domestic debt'!B14*1000)))*100 -> 20.500944 | J15: =('Portfolio debt assets '!L14)/(('Portfolio debt assets '!L14+('Domestic debt'!L14*1000)))*100 -> 32.048578 | K15: =(100-I15)/100 -> 0.79499056 | L15: =(100-J15)/100 -> 0.67951422
B16: Japan | C16: =('Portfolio equity assets '!B15)/('Portfolio equity assets '!B15+('Market Cap'!B15/1000000)-'Portfolio equity liabilities '!B15)*100 -> 3.8196196 | D16: =('Portfolio equity assets '!L15)/('Portfolio equity assets '!L15+('Market Cap'!L15/1000000)-'Portfolio equity liabilities '!L15)*100 -> 10.292692 | E16: =('Portfolio equity assets '!AE15)/('Portfolio equity assets '!AE15+('Market Cap'!AE15/1000000)-'Portfolio equity liabilities '!AE15)*100 -> 33.352701 | F16: =(100-C16)/100 -> 0.9618038 | G16: =(100-D16)/100 -> 0.89707308 | H16: =(100-E16)/100 -> 0.66647299 | I16: =('Portfolio debt assets '!B15)/(('Portfolio debt assets '!B15+('Domestic debt'!B15*1000)))*100 -> 31.260963 | J16: =('Portfolio debt assets '!L15)/(('Portfolio debt assets '!L15+('Domestic debt'!L15*1000)))*100 -> 22.822034 | K16: =(100-I16)/100 -> 0.68739037 | L16: =(100-J16)/100 -> 0.77177966
B17: Mexico | C17: =('Portfolio equity assets '!B16)/('Portfolio equity assets '!B16+('Market Cap'!B16/1000000)-'Portfolio equity liabilities '!B16)*100 -> 1.1584901 | D17: =('Portfolio equity assets '!L16)/('Portfolio equity assets '!L16+('Market Cap'!L16/1000000)-'Portfolio equity liabilities '!L16)*100 -> 12.484908 | E17: =('Portfolio equity assets '!AE16)/('Portfolio equity assets '!AE16+('Market Cap'!AE16/1000000)-'Portfolio equity liabilities '!AE16)*100 -> 17.190776 | F17: =(100-C17)/100 -> 0.9884151 | G17: =(100-D17)/100 -> 0.87515092 | H17: =(100-E17)/100 -> 0.82809224 | I17: =('Portfolio debt assets '!B16)/(('Portfolio debt assets '!B16+('Domestic debt'!B16*1000)))*100 -> 34.455668 | J17: =('Portfolio debt assets '!L16)/(('Portfolio debt assets '!L16+('Domestic debt'!L16*1000)))*100 -> 24.493424 | K17: =(100-I17)/100 -> 0.65544332 | L17: =(100-J17)/100 -> 0.75506576
B18: Netherlands | C18: =('Portfolio equity assets '!B17)/('Portfolio equity assets '!B17+('Market Cap'!B17/1000000)-'Portfolio equity liabilities '!B17)*100 -> 40.032453 | D18: =('Portfolio equity assets '!L17)/('Portfolio equity assets '!L17+('Market Cap'!L17/1000000)-'Portfolio equity liabilities '!L17)*100 -> 68.52532 | E18: -- | F18: =(100-C18)/100 -> 0.59967547 | G18: =(100-D18)/100 -> 0.3147468 | H18: --- | I18: =('Portfolio debt assets '!B17)/(('Portfolio debt assets '!B17+('Domestic debt'!B17*1000)))*100 -> 54.863226 | J18: =('Portfolio debt assets '!L17)/(('Portfolio debt assets '!L17+('Domestic debt'!L17*1000)))*100 -> 65.737464 | K18: =(100-I18)/100 -> 0.45136774 | L18: =(100-J18)/100 -> 0.34262536
B19: New Zealand | C19: =('Portfolio equity assets '!B18)/('Portfolio equity assets '!B18+('Market Cap'!B18/1000000)-'Portfolio equity liabilities '!B18)*100 -> 2.7978741 | D19: =('Portfolio equity assets '!L18)/('Portfolio equity assets '!L18+('Market Cap'!L18/1000000)-'Portfolio equity liabilities '!L18)*100 -> 42.602803 | E19: =('Portfolio equity assets '!AE18)/('Portfolio equity assets '!AE18+('Market Cap'!AE18/1000000)-'Portfolio equity liabilities '!AE18)*100 -> 62.663966 | F19: =(100-C19)/100 -> 0.97202126 | G19: =(100-D19)/100 -> 0.57397197 | H19: =(100-E19)/100 -> 0.37336034 | I19: =('Portfolio debt assets '!B18)/(('Portfolio debt assets '!B18+('Domestic debt'!B18*1000)))*100 -> 11.826851 | J19: =('Portfolio debt assets '!L18)/(('Portfolio debt assets '!L18+('Domestic debt'!L18*1000)))*100 -> 45.644607 | K19: =(100-I19)/100 -> 0.88173149 | L19: =(100-J19)/100 -> 0.54355393
B20: Norway | C20: =('Portfolio equity assets '!B19)/('Portfolio equity assets '!B19+('Market Cap'!B19/1000000)-'Portfolio equity liabilities '!B19)*100 -> 22.234175 | D20: =('Portfolio equity assets '!L19)/('Portfolio equity assets '!L19+('Market Cap'!L19/1000000)-'Portfolio equity liabilities '!L19)*100 -> 50.98558 | E20: -- | F20: =(100-C20)/100 -> 0.77765825 | G20: =(100-D20)/100 -> 0.4901442 | H20: --- | I20: =('Portfolio debt assets '!B19)/(('Portfolio debt assets '!B19+('Domestic debt'!B19*1000)))*100 -> 34.618779 | J20: =('Portfolio debt assets '!L19)/(('Portfolio debt assets '!L19+('Domestic debt'!L19*1000)))*100 -> 69.115971 | K20: =(100-I20)/100 -> 0.65381221 | L20: =(100-J20)/100 -> 0.30884029
B21: Portugal | C21: -- | D21: =('Portfolio equity assets '!L20)/('Portfolio equity assets '!L20+('Market Cap'!L20/1000000)-'Portfolio equity liabilities '!L20)*100 -> 37.378884 | E21: -- | F21: -- | G21: =(100-D21)/100 -> 0.62621116 | H21: -- | I21: =('Portfolio debt assets '!B20)/(('Portfolio debt assets '!B20+('Domestic debt'!B20*1000)))*100 -> 37.429491 | J21: =('Portfolio debt assets '!L20)/(('Portfolio debt assets '!L20+('Domestic debt'!L20*1000)))*100 -> 67.402181 | K21: =(100-I21)/100 -> 0.62570509 | L21: =(100-J21)/100 -> 0.32597819
B22: Spain | C22: =('Portfolio equity assets '!B21)/('Portfolio equity assets '!B21+('Market Cap'!B21/1000000)-'Portfolio equity liabilities '!B21)*100 -> 5.8474452 | D22: =('Portfolio equity assets '!L21)/('Portfolio equity assets '!L21+('Market Cap'!L21/1000000)-'Portfolio equity liabilities '!L21)*100 -> 13.051181 | E22: =('Portfolio equity assets '!AE21)/('Portfolio equity assets '!AE21+('Market Cap'!AE21/1000000)-'Portfolio equity liabilities '!AE21)*100 -> 53.848491 | F22: =(100-C22)/100 -> 0.94152555 | G22: =(100-D22)/100 -> 0.86948819 | H22: =(100-E22)/100 -> 0.46151509 | I22: =('Portfolio debt assets '!B21)/(('Portfolio debt assets '!B21+('Domestic debt'!B21*1000)))*100 -> 36.687217 | J22: =('Portfolio debt assets '!L21)/(('Portfolio debt assets '!L21+('Domestic debt'!L21*1000)))*100 -> 53.281968 | K22: =(100-I22)/100 -> 0.63312783 | L22: =(100-J22)/100 -> 0.46718032
B23: Sweden | C23: =('Portfolio equity assets '!B22)/('Portfolio equity assets '!B22+('Market Cap'!B22/1000000)-'Portfolio equity liabilities '!B22)*100 -> 16.05475 | D23: =('Portfolio equity assets '!L22)/('Portfolio equity assets '!L22+('Market Cap'!L22/1000000)-'Portfolio equity liabilities '!L22)*100 -> 41.599128 | E23: -- | F23: =(100-C23)/100 -> 0.8394525 | G23: =(100-D23)/100 -> 0.58400872 | H23: -- | I23: =('Portfolio debt assets '!B22)/(('Portfolio debt assets '!B22+('Domestic debt'!B22*1000)))*100 -> 21.763608 | J23: =('Portfolio debt assets '!L22)/(('Portfolio debt assets '!L22+('Domestic debt'!L22*1000)))*100 -> 39.288288 | K23: =(100-I23)/100 -> 0.78236392 | L23: =(100-J23)/100 -> 0.60711712
B24: Switzerland | C24: =('Portfolio equity assets '!B23)/('Portfolio equity assets '!B23+('Market Cap'!B23/1000000)-'Portfolio equity liabilities '!B23)*100 -> 40.281826 | D24: =('Portfolio equity assets '!L23)/('Portfolio equity assets '!L23+('Market Cap'!L23/1000000)-'Portfolio equity liabilities '!L23)*100 -> 47.506767 | E24: =('Portfolio equity assets '!AE23)/('Portfolio equity assets '!AE23+('Market Cap'!AE23/1000000)-'Portfolio equity liabilities '!AE23)*100 -> 63.430012 | F24: =(100-C24)/100 -> 0.59718174 | G24: =(100-D24)/100 -> 0.52493233 | H24: =(100-E24)/100 -> 0.36569988 | I24: =('Portfolio debt assets '!B23)/(('Portfolio debt assets '!B23+('Domestic debt'!B23*1000)))*100 -> 71.428428 | J24: =('Portfolio debt assets '!L23)/(('Portfolio debt assets '!L23+('Domestic debt'!L23*1000)))*100 -> 82.235767 | K24: =(100-I24)/100 -> 0.28571572 | L24: =(100-J24)/100 -> 0.17764233
B25: Turkey | C25: =('Portfolio equity assets '!B24)/('Portfolio equity assets '!B24+('Market Cap'!B24/1000000)-'Portfolio equity liabilities '!B24)*100 -> 1.827136 | D25: =('Portfolio equity assets '!L24)/('Portfolio equity assets '!L24+('Market Cap'!L24/1000000)-'Portfolio equity liabilities '!L24)*100 -> 2.3324543 | E25: =('Portfolio equity assets '!AE24)/('Portfolio equity assets '!AE24+('Market Cap'!AE24/1000000)-'Portfolio equity liabilities '!AE24)*100 -> 1.0591876 | F25: =(100-C25)/100 -> 0.98172864 | G25: =(100-D25)/100 -> 0.97667546 | H25: =(100-E25)/100 -> 0.98940812 | I25: =('Portfolio debt assets '!B24)/(('Portfolio debt assets '!B24+('Domestic debt'!B24*1000)))*100 -> 49.117465 | J25: =('Portfolio debt assets '!L24)/(('Portfolio debt assets '!L24+('Domestic debt'!L24*1000)))*100 -> 21.359051 | K25: =(100-I25)/100 -> 0.50882535 | L25: =(100-J25)/100 -> 0.78640949
B26: United Kingdom | C26: =('Portfolio equity assets '!B25)/('Portfolio equity assets '!B25+('Market Cap'!B25/1000000)-'Portfolio equity liabilities '!B25)*100 -> 23.184173 | D26: =('Portfolio equity assets '!L25)/('Portfolio equity assets '!L25+('Market Cap'!L25/1000000)-'Portfolio equity liabilities '!L25)*100 -> 36.169864 | E26: =('Portfolio equity assets '!AE25)/('Portfolio equity assets '!AE25+('Market Cap'!AE25/1000000)-'Portfolio equity liabilities '!AE25)*100 -> 67.559222 | F26: =(100-C26)/100 -> 0.76815827 | G26: =(100-D26)/100 -> 0.63830136 | H26: =(100-E26)/100 -> 0.32440778 | I26: =('Portfolio debt assets '!B25)/(('Portfolio debt assets '!B25+('Domestic debt'!B25*1000)))*100 -> 77.189875 | J26: =('Portfolio debt assets '!L25)/(('Portfolio debt assets '!L25+('Domestic debt'!L25*1000)))*100 -> 84.025945 | K26: =(100-I26)/100 -> 0.22810125 | L26: =(100-J26)/100 -> 0.15974055
B27: United States | C27: =('Portfolio equity assets '!B26)/('Portfolio equity assets '!B26+('Market Cap'!B26/1000000)-'Portfolio equity liabilities '!B26)*100 -> 10.031725 | D27: =('Portfolio equity assets '!L26)/('Portfolio equity assets '!L26+('Market Cap'!L26/1000000)-'Portfolio equity liabilities '!L26)*100 -> 14.334733 | E27: =('Portfolio equity assets '!AE26)/('Portfolio equity assets '!AE26+('Market Cap'!AE26/1000000)-'Portfolio equity liabilities '!AE26)*100 -> 26.734185 | F27: =(100-C27)/100 -> 0.89968275 | G27: =(100-D27)/100 -> 0.85665267 | H27: =(100-E27)/100 -> 0.73265815 | I27: =('Portfolio debt assets '!B26)/(('Portfolio debt assets '!B26+('Domestic debt'!B26*1000)))*100 -> 12.836217 | J27: =('Portfolio debt assets '!L26)/(('Portfolio debt assets '!L26+('Domestic debt'!L26*1000)))*100 -> 16.580956 | K27: =(100-I27)/100 -> 0.87163783 | L27: =(100-J27)/100 -> 0.83419044
B29: Average | C29: =AVERAGE(C4:C11,C15:C20,C22:C27) -> 16.457392 | D29: =AVERAGE(D4:D8,D10:D12,D15:D27) -> 32.908299 | E29: =AVERAGE(E4:E27) -> 44.733075 | F29: =AVERAGE(F4:F27) -> 0.83542608 | G29: =AVERAGE(G4:G27) -> 0.67091701 | H29: =AVERAGE(H4:H27) -> 0.55266925 | I29: =AVERAGE(I4:I27) -> 35.558184 | J29: =AVERAGE(J4:J27) -> 47.903021 | K29: =AVERAGE(K4:K27) -> 0.64441816 | L29: =AVERAGE(L4:L27) -> 0.52096979

Sheet Portfolio equity assets 
A1: Country | K1: Portfolio equity assets
A2: Year | B2: 1993 | C2: 1994 | D2: 1995 | E2: 1996 | F2: 1997 | G2: 1998 | H2: 1999 | I2: 2000 | J2: 2001 | K2: 2002 | L2: 2003 | M2: 2004 | N2: 2005 | O2: 2006 | P2: 2007 | Q2: 2008 | R2: 2009 | S2: 2010 | T2: 2011 | U2: 2012 | V2: 2013 | W2: 2014 | X2: 2015 | Y2: 2016 | Z2: 2017 | AA2: 2018 | AB2: 2019 | AC2: 2020 | AD2: 2021 | AE2: 2022
A3: Australia | B3: 21523.655 | C3: 22662.363 | D3: 27175.365 | E3: 31681.588 | F3: 33076.226 | G3: 36782.433 | H3: 57208.808 | I3: 59195.454 | J3: 60057.793 | K3: 65500.847 | L3: 92943 | M3: 114631.41 | N3: 137520.33 | O3: 188372.13 | P3: 267546.2 | Q3: 161055.22 | R3: 244571.18 | S3: 283837.35 | T3: 299082.01 | U3: 360778.81 | V3: 396083.77 | W3: 420691.24 | X3: 394464.82 | Y3: 427599.84 | Z3: 526353.36 | AA3: 502371.5 | AB3: 620559.25 | AC3: 692134.07 | AD3: 867650.71 | AE3: 725581.5
A4: Austria | B4: 3722.3091 | C4: 4941.1979 | D4: 5868.3584 | E4: 6454.2633 | F4: 11501.623 | G4: 17225.266 | H4: 28935.795 | I4: 42698.319 | J4: 31190.32 | K4: 30047.485 | L4: 44150.093 | M4: 54934.612 | N4: 63610.77 | O4: 88108.617 | P4: 100796.16 | Q4: 54860.814 | R4: 75206.523 | S4: 87505.066 | T4: 74039.546 | U4: 86708.329 | V4: 101631.4 | W4: 99761.383 | X4: 97545.343 | Y4: 106821.44 | Z4: 142346.12 | AA4: 126840.81 | AB4: 158578.02 | AC4: 184369.32 | AD4: 213787.31 | AE4: 181068.15
A5: Belgium | B5: 59318.748 | C5: 59803.691 | D5: 63766.786 | E5: 64571.161 | F5: 64661.43 | G5: 94141.636 | H5: 125273.62 | I5: 124687 | J5: 110225.95 | K5: 104970.68 | L5: 146643.14 | M5: 172163.99 | N5: 204559.98 | O5: 248209.72 | P5: 313728.06 | Q5: 233392.27 | R5: 261133.24 | S5: 260080.64 | T5: 219124.55 | U5: 257308.07 | V5: 312373.05 | W5: 317052.5 | X5: 306907.8 | Y5: 339554.07 | Z5: 430389.19 | AA5: 363493.99 | AB5: 439410.05 | AC5: 513156.04 | AD5: 574769.58 | AE5: 475011.38
A6: Canada | B6: 69689.522 | C6: 74056.706 | D6: 89141.308 | E6: 117443.82 | F6: 138738.32 | G6: 155873.52 | H6: 235440.45 | I6: 239948.03 | J6: 230766.92 | K6: 203461.21 | L6: 275909.88 | M6: 319840.21 | N6: 382600.37 | O6: 499606.16 | P6: 608457.26 | Q6: 359016.78 | R6: 478116.57 | S6: 580362.94 | T6: 584147.26 | U6: 702729.35 | V6: 857015.11 | W6: 934684.26 | X6: 926438.48 | Y6: 1012797.9 | Z6: 1333310.2 | AA6: 1200859.2 | AB6: 1370524.1 | AC6: 1588606.3 | AD6: 2055860.3 | AE6: 1572584.4
A7: Denmark | B7: 7973.4219 | C7: 8877.1988 | D7: 10818.608 | E7: 16149.382 | F7: 22414.298 | G7: 32622.876 | H7: 50132.319 | I7: 56480.145 | J7: 47977.516 | K7: 35795.858 | L7: 52117.83 | M7: 65428.116 | N7: 88374.156 | O7: 132046.84 | P7: 156759.4 | Q7: 85198.774 | R7: 115037.28 | S7: 136051.34 | T7: 129215.57 | U7: 161706.81 | V7: 206434.87 | W7: 216415.69 | X7: 211300.73 | Y7: 231384.56 | Z7: 303430.26 | AA7: 289992.64 | AB7: 345591.76 | AC7: 422701.23 | AD7: 493882.06 | AE7: 396700.61
A8: Finland | B8: 308.23753 | C8: 418.49384 | D8: 737.8516 | E8: 1563.5565 | F8: 3245.3373 | G8: 5270.8006 | H8: 13669.592 | I8: 20263.499 | J8: 20157.094 | K8: 22943.123 | L8: 36081.889 | M8: 53281.593 | N8: 64511.246 | O8: 96258.476 | P8: 122329.98 | Q8: 63345.508 | R8: 103086.09 | S8: 131659.42 | T8: 113492.78 | U8: 139731.86 | V8: 164838.31 | W8: 169793.1 | X8: 169585.71 | Y8: 176148.54 | Z8: 222309.44 | AA8: 208027.04 | AB8: 242316.26 | AC8: 280600.96 | AD8: 320915.41 | AE8: 280846.45
A9: France | B9: 51965.058 | C9: 53744.856 | D9: 58363.265 | E9: 73519.19 | F9: 99126.601 | G9: 143051.53 | H9: 190673.08 | I9: 210060.38 | J9: 201747.2 | K9: 200095.11 | L9: 340240.83 | M9: 442653.9 | N9: 524887.46 | O9: 716800.96 | P9: 826859.43 | Q9: 474750.98 | R9: 646027.6 | S9: 665773.54 | T9: 519334.68 | U9: 652646.49 | V9: 812303.69 | W9: 770696.11 | X9: 748029.44 | Y9: 753755.08 | Z9: 954263.7 | AA9: 786403.52 | AB9: 912445.25 | AC9: 1044512.9 | AD9: 1182670.4 | AE9: 926568.54
A10: Germany | B10: 115203.61 | C10: 145785.12 | D10: 165971.4 | E10: 187491.64 | F10: 241387.2 | G10: 370572.03 | H10: 507080.89 | I10: 573062.38 | J10: 490736.04 | K10: 437829.1 | L10: 576236.17 | M10: 668229.91 | N10: 771379.88 | O10: 884233.8 | P10: 954029.74 | Q10: 589528.3 | R10: 707088.26 | S10: 739717.65 | T10: 647169.96 | U10: 747412.39 | V10: 919610.08 | W10: 939768.03 | X10: 952012.63 | Y10: 1009044.6 | Z10: 1354430.7 | AA10: 1214344.6 | AB10: 1492139.2 | AC10: 1798381.3 | AD10: 2153346.7 | AE10: 1798676.9
A11: Greece | B11: 391.66038 | C11: 411.84906 | D11: 510.77358 | E11: 593.54717 | F11: 999.33962 | G11: 1177 | H11: 1147.2532 | I11: 1345.503 | J11: 2559.2952 | K11: 2596.5812 | L11: 4386.399 | M11: 5649.9908 | N11: 7837.9268 | O11: 12810.459 | P11: 19997.006 | Q11: 15432.561 | R11: 13728.918 | S11: 12246.273 | T11: 11603.695 | U11: 6852.9636 | V11: 7094.0904 | W11: 8155.1097 | X11: 14272.857 | Y11: 11558.207 | Z11: 11402.944 | AA11: 9382.13 | AB11: 10619.5 | AC11: 11993.675 | AD11: 15059.05 | AE11: 12453.622
A12: Iceland | B12: 22.057001 | C12: 47.58833 | D12: 102.37621 | E12: 182.2694 | F12: 397.28457 | G12: 830.04905 | H12: 1713.122 | I12: 2012.4439 | J12: 1754.4342 | K12: 1848.4239 | L12: 3183.054 | M12: 5841.5793 | N12: 9339.4093 | O12: 13392.576 | P12: 20630.703 | Q12: 6706.2863 | R12: 5893.0024 | S12: 4935.4976 | T12: 4678.4125 | U12: 4983.5801 | V12: 5904.6127 | W12: 6051.844 | X12: 6294.0196 | Y12: 7759.883 | Z12: 10150.364 | AA12: 9912.4989 | AB12: 12999.571 | AC12: 16021.877 | AD12: 19863.169 | AE12: 17384.054
A13: Ireland | B13: 13322.184 | C13: 14941.582 | D13: 21132.554 | E13: 26887.85 | F13: 39803.458 | G13: 60785.342 | H13: 118794.95 | I13: 130898.09 | J13: 133758.43 | K13: 152856.41 | L13: 222502.71 | M13: 304942.86 | N13: 383154.76 | O13: 573199.23 | P13: 649172.55 | Q13: 427868.42 | R13: 539873.49 | S13: 603914.3 | T13: 563101.4 | U13: 660459.97 | V13: 848083.06 | W13: 937974.81 | X13: 957468.1 | Y13: 1004338 | Z13: 1330108.9 | AA13: 1253337.6 | AB13: 1563927.8 | AC13: 1913370.4 | AD13: 2324136 | AE13: 1912680.4
... A26: United States | B26: 543862 | C26: 626762 | D26: 790615 | E26: 1006135 | F26: 1207787 | G26: 1474983 | H26: 2003716 | I26: 1852842 | J26: 1612673 | K26: 1373980 | L26: 2079422 | M26: 2560418 | N26: 3317705 | O26: 4328960 | P26: 5247990 | Q26: 2748428 | R26: 3995295 | S26: 4900246 | T26: 4501438 | U26: 5321857 | V26: 6472877 | W26: 6770629 | X26: 6756163 | Y26: 7146320 | Z26: 9118138 | AA26: 7899563 | AB26: 9478014 | AC26: 10615016 | AD26: 12061294 | AE26: 10305962

Sheet Portfolio debt assets 
A1: Country | K1: Portfolio debt assets
A2: Year | B2: 1993 | C2: 1994 | D2: 1995 | E2: 1996 | F2: 1997 | G2: 1998 | H2: 1999 | I2: 2000 | J2: 2001 | K2: 2002 | L2: 2003 | M2: 2004 | N2: 2005 | O2: 2006 | P2: 2007 | Q2: 2008 | R2: 2009 | S2: 2010 | T2: 2011 | U2: 2012 | V2: 2013 | W2: 2014 | X2: 2015 | Y2: 2016 | Z2: 2017 | AA2: 2018 | AB2: 2019 | AC2: 2020 | AD2: 2021 | AE2: 2022
A3: Australia | B3: 26138.768 | C3: 28053.354 | D3: 33098.115 | E3: 41645.804 | F3: 46181.137 | G3: 48065.915 | H3: 56233.992 | I3: 58248.114 | J3: 58008.245 | K3: 72792.371 | L3: 99926.25 | M3: 127040.1 | N3: 157851.89 | O3: 217230.84 | P3: 277487.13 | Q3: 255428.43 | R3: 348938.94 | S3: 427494.4 | T3: 460154.14 | U3: 514079.84 | V3: 512353.56 | W3: 527894.66 | X3: 562039.62 | Y3: 562939.82 | Z3: 597499.5 | AA3: 580068.79 | AB3: 589035.76 | AC3: 640523.74 | AD3: 636264.85 | AE3: 629815.52
A4: Austria | B4: 88487.194 | C4: 99772.085 | D4: 116574.15 | E4: 116578.42 | F4: 117402.2 | G4: 132481.69 | H4: 157599.04 | I4: 174967.13 | J4: 191173.72 | K4: 247000.38 | L4: 327260.91 | M4: 409582.11 | N4: 428661.97 | O4: 575513.2 | P4: 701683.83 | Q4: 694587.73 | R4: 699033.86 | S4: 636132.75 | T4: 635403.24 | U4: 641996.29 | V4: 655497.26 | W4: 576676.86 | X4: 495064.55 | Y4: 464116.01 | Z4: 522925.98 | AA4: 499839.45 | AB4: 520661.07 | AC4: 571165.97 | AD4: 542522.2 | AE4: 512408.51
A5: Belgium | B5: 324619.22 | C5: 380651.75 | D5: 433460.58 | E5: 433144.66 | F5: 425554.63 | G5: 450961.75 | H5: 468771.47 | I5: 436784.14 | J5: 459931.96 | K5: 575445.81 | L5: 768175.55 | M5: 943412.25 | N5: 959219.97 | O5: 1138815.2 | P5: 1479354.5 | Q5: 1400217.2 | R5: 1366985.3 | S5: 1225052.2 | T5: 1229933.5 | U5: 1158856.7 | V5: 1066158.8 | W5: 983476.85 | X5: 880277.09 | Y5: 899150.46 | Z5: 948834.59 | AA5: 853568.88 | AB5: 886542.34 | AC5: 984818.92 | AD5: 936878.79 | AE5: 884435.39
A6: Canada | B6: 100141.66 | C6: 117441.26 | D6: 136800.22 | E6: 152605.29 | F6: 163079.89 | G6: 160368.16 | H6: 150871.18 | I6: 154029.4 | J6: 159645.59 | K6: 165005.06 | L6: 193738.68 | M6: 227670.36 | N6: 272482.53 | O6: 352961.73 | P6: 448896.77 | Q6: 431263.49 | R6: 502999.98 | S6: 563581.24 | T6: 602639.26 | U6: 667458.87 | V6: 669767.2 | W6: 733082.76 | X6: 768649.78 | Y6: 856410.86 | Z6: 940679.26 | AA6: 1018184 | AB6: 1287955.8 | AC6: 1410389.8 | AD6: 1468070.6 | AE6: 1619566.3
A7: Denmark | B7: 77076.412 | C7: 71181.983 | D7: 75549.946 | E7: 87307.595 | F7: 86580.721 | G7: 101591.64 | H7: 92683.949 | I7: 97502.151 | J7: 97689.715 | K7: 127061.19 | L7: 176731.09 | M7: 220596.33 | N7: 232955.36 | O7: 280065.18 | P7: 369626.43 | Q7: 372857.95 | R7: 364452.13 | S7: 381430.53 | T7: 360886.24 | U7: 386395.36 | V7: 415542.89 | W7: 397260.76 | X7: 346554.32 | Y7: 368323.22 | Z7: 430470.38 | AA7: 373999.91 | AB7: 411131.98 | AC7: 491106.05 | AD7: 463041.52 | AE7: 404780.7
A8: Finland | B8: 25487.078 | C8: 27393.321 | D8: 30987.932 | E8: 38321.885 | F8: 37798.808 | G8: 41238.422 | H8: 50299.317 | I8: 64498.538 | J8: 78155.447 | K8: 100101.11 | L8: 137628.62 | M8: 179332.52 | N8: 170366.71 | O8: 221463.4 | P8: 263065.55 | Q8: 258443.24 | R8: 305137.58 | S8: 339007.38 | T8: 407586.03 | U8: 436804.42 | V8: 413356.26 | W8: 379844.54 | X8: 345345.44 | Y8: 307568.46 | Z8: 305190.67 | AA8: 397979.1 | AB8: 401951.4 | AC8: 426375.53 | AD8: 377410.64 | AE8: 387974.68
A9: France | B9: 661604.61 | C9: 764904.6 | D9: 859826.53 | E9: 834072.94 | F9: 902324.61 | G9: 1016148.8 | H9: 1042245.9 | I9: 1077138.3 | J9: 1206508 | K9: 1521666.6 | L9: 1926305.5 | M9: 2389202.9 | N9: 2589121.2 | O9: 3240223.3 | P9: 4157506.6 | Q9: 3977795.2 | R9: 4229386.1 | S9: 4200082.9 | T9: 4007022.5 | U9: 4098596 | V9: 4233474.3 | W9: 4060829.4 | X9: 3697489.8 | Y9: 3691708.8 | Z9: 4210994.4 | AA9: 4416991.3 | AB9: 4703592.6 | AC9: 5533484.7 | AD9: 5366136.8 | AE9: 5130016.3
A10: Germany | B10: 943696.92 | C10: 1024490.6 | D10: 1179105.7 | E10: 1185146 | F10: 1140963.7 | G10: 1393041.8 | H10: 1457271.8 | I10: 1512242.1 | J10: 1645212.6 | K10: 2094684.9 | L10: 2699701.7 | M10: 3212139.6 | N10: 3145739.7 | O10: 4013889.4 | P10: 5040788.4 | Q10: 4909145.2 | R10: 5060879.7 | S10: 5100371.6 | T10: 5094966.7 | U10: 5448611.4 | V10: 5502871 | W10: 5213522.7 | X10: 4784533.8 | Y10: 4898735.8 | Z10: 5725828.8 | AA10: 5681178.6 | AB10: 5792206.6 | AC10: 6790355.4 | AD10: 6673967.8 | AE10: 6078755
A11: Greece | B11: 19082.09 | C11: 26281.756 | D11: 33398.12 | E11: 41127.349 | F11: 40491.874 | G11: 42052 | H11: 43991.434 | I11: 37728.984 | J11: 43916.06 | K11: 62865.24 | L11: 91890.702 | M11: 117944.63 | N11: 130944.95 | O11: 161107.63 | P11: 228234.62 | Q11: 260456.5 | R11: 304147.55 | S11: 245937.02 | T11: 233385.8 | U11: 281337.04 | V11: 258422.4 | W11: 225626.25 | X11: 213715.43 | Y11: 199731.36 | Z11: 190794.59 | AA11: 180693.08 | AB11: 210626.22 | AC11: 272803.48 | AD11: 290163.11 | AE11: 278647.26
A12: Iceland | B12: 219.7026 | C12: 318.35508 | D12: 297.13322 | E12: 331.30513 | F12: 408.36797 | G12: 514.71437 | H12: 688.03584 | I12: 588.42975 | J12: 966.61486 | K12: 1625.3413 | L12: 4150.2324 | M12: 8432.8145 | N12: 19573.134 | O12: 36387.176 | P12: 60770.897 | Q12: 16696.384 | R12: 13847.638 | S12: 14345.215 | T12: 12163.45 | U12: 16972.021 | V12: 18314.409 | W12: 14529.669 | X12: 10306.822 | Y12: 5749.805 | Z12: 5828.6344 | AA12: 6426.124 | AB12: 5583.8398 | AC12: 5928.2761 | AD12: 5952.3393 | AE12: 6201.056
A13: Ireland | B13: 40702.393 | C13: 55200.339 | D13: 83239.762 | E13: 124466.23 | F13: 197007.63 | G13: 335797.65 | H13: 422184.15 | I13: 468654.7 | J13: 561139.57 | K13: 750674.14 | L13: 1057107 | M13: 1333807.8 | N13: 1484361.1 | O13: 1942848.9 | P13: 2503780.1 | Q13: 2390569 | R13: 2433743.9 | S13: 2325995.5 | T13: 2496352.3 | U13: 2551529.6 | V13: 2629499.6 | W13: 2626888.7 | X13: 2670648.6 | Y13: 2687101.2 | Z13: 3246054.2 | AA13: 3235685.3 | AB13: 3797071.8 | AC13: 4455046.7 | AD13: 4715624.3 | AE13: 4288070.1
... A26: United States | B26: 1321315 | C26: 1410397 | D26: 1634090 | E26: 1875623 | F26: 2157220 | G26: 2278536 | H26: 2419905 | I26: 2726514 | J26: 2873499 | K26: 3250042 | L26: 3321241 | M26: 4092756 | N26: 4614054 | O26: 5692811 | P26: 6762711 | Q26: 6547273 | R26: 6592975 | S26: 7240924 | T26: 7239763 | U26: 7027158 | V26: 7010835 | W26: 7107799 | X26: 6661504 | Y26: 6726621 | Z26: 7559472 | AA26: 7891171 | AB26: 8393516 | AC26: 8885433 | AD26: 9339840 | AE26: 8798611

Sheet Portfolio equity liabilities 
A1: Country | K1: Portfolio equity liabilities
A2: Year | B2: 1993 | C2: 1994 | D2: 1995 | E2: 1996 | F2: 1997 | G2: 1998 | H2: 1999 | I2: 2000 | J2: 2001 | K2: 2002 | L2: 2003 | M2: 2004 | N2: 2005 | O2: 2006 | P2: 2007 | Q2: 2008 | R2: 2009 | S2: 2010 | T2: 2011 | U2: 2012 | V2: 2013 | W2: 2014 | X2: 2015 | Y2: 2016 | Z2: 2017 | AA2: 2018 | AB2: 2019 | AC2: 2020 | AD2: 2021 | AE2: 2022
A3: Australia | B3: 35939.114 | C3: 46570.712 | D3: 51341.675 | E3: 61154.48 | F3: 60327.104 | G3: 73020.337 | H3: 100804.85 | I3: 84947.036 | J3: 89130.336 | K3: 87368.057 | L3: 138978 | M3: 146733.22 | N3: 182379.48 | O3: 252366.14 | P3: 325898.43 | Q3: 173251.27 | R3: 336652.31 | S3: 402395.85 | T3: 341019.18 | U3: 398184.78 | V3: 386835.8 | W3: 373755.3 | X3: 335907.96 | Y3: 381296.68 | Z3: 458655.6 | AA3: 385148 | AB3: 462936.86 | AC3: 528446.54 | AD3: 583314.19 | AE3: 565014.68
A4: Austria | B4: 3590.546 | C4: 5378.7948 | D4: 6988.5012 | E4: 9056.0526 | F4: 15661.68 | G4: 15622.806 | H4: 14745.016 | I4: 19569.345 | J4: 14919.797 | K4: 17235.445 | L4: 26470.54 | M4: 45181.277 | N4: 59235.693 | O4: 92955.177 | P4: 105124.13 | Q4: 46804.263 | R4: 60307.838 | S4: 62709.202 | T4: 47413.672 | U4: 57855.69 | V4: 65576.205 | W4: 54785.048 | X4: 54703.909 | Y4: 56828.639 | Z4: 85998.205 | AA4: 63700.93 | AB4: 73615.279 | AC4: 78889.032 | AD4: 92830.161 | AE4: 67491.248
A5: Belgium | B5: 8252.5616 | C5: 9736.9454 | D5: 10011.899 | E5: 11173.254 | F5: 12099.133 | G5: 17842.63 | H5: 15470.84 | I5: 14236.65 | J5: 15663.345 | K5: 18059.663 | L5: 27884.514 | M5: 44250.543 | N5: 43015.401 | O5: 57745.182 | P5: 72899.864 | Q5: 55814.128 | R5: 107402.49 | S5: 107017.59 | T5: 99243.424 | U5: 141514.89 | V5: 187040.44 | W5: 195273.42 | X5: 215728.08 | Y5: 219182.18 | Z5: 264747.87 | AA5: 190408.92 | AB5: 235456.78 | AC5: 229875.1 | AD5: 241155.46 | AE5: 199455.27
A6: Canada | B6: 41005.843 | C6: 44812.446 | D6: 57054.99 | E6: 79913.583 | F6: 84974.68 | G6: 92862.18 | H6: 145243.82 | I6: 152328.56 | J6: 113270.3 | K6: 99394.957 | L6: 172321.6 | M6: 225899.24 | N6: 280843.39 | O6: 346101.13 | P6: 418081.03 | Q6: 209170.89 | R6: 353642.88 | S6: 462355.38 | T6: 409846.95 | U6: 442094.38 | V6: 432507.14 | W6: 449884.5 | X6: 357797.21 | Y6: 463699.33 | Z6: 586724.59 | AA6: 507835.46 | AB6: 625580.04 | AC6: 638867.23 | AD6: 791566.1 | AE6: 702797.35
A7: Denmark | B7: 3248.4312 | C7: 6740.0953 | D7: 8294.2661 | E7: 12448.482 | F7: 20363.317 | G7: 20556.173 | H7: 20740.255 | I7: 26023.315 | J7: 23842.4 | K7: 20671.503 | L7: 31257.85 | M7: 44458.783 | N7: 49096.63 | O7: 62886.389 | P7: 83226.213 | Q7: 45686.2 | R7: 67033.39 | S7: 92773.591 | T7: 78595.447 | U7: 107299.57 | V7: 146634.58 | W7: 165487.63 | X7: 202786.82 | Y7: 172432.65 | Z7: 236789.63 | AA7: 186779 | AB7: 238411.15 | AC7: 343747.85 | AD7: 412086.81 | AE7: 373504.78
A8: Finland | B8: 5251.1021 | C8: 12767.33 | D8: 14625.338 | E8: 23456.793 | F8: 28870.257 | G8: 79721.743 | H8: 219531.22 | I8: 204361.06 | J8: 128038.79 | K8: 89172.754 | L8: 103315.11 | M8: 102974.34 | N8: 119951.97 | O8: 154812.8 | P8: 229908.31 | Q8: 96964.179 | R8: 104051.7 | S8: 97396.473 | T8: 66877.77 | U8: 83513.455 | V8: 113430.98 | W8: 110717.42 | X8: 112005.46 | Y8: 119495.94 | Z8: 147852.1 | AA8: 160208.4 | AB8: 167796.64 | AC8: 203844.62 | AD8: 247221.66 | AE8: 194283.32
A9: France | B9: 103818.17 | C9: 102207.26 | D9: 120755.1 | E9: 155317.93 | F9: 208580.35 | G9: 300439.34 | H9: 482208 | I9: 502116.41 | J9: 415991.23 | K9: 345112.49 | L9: 490900.31 | M9: 593864.7 | N9: 690443.02 | O9: 990330 | P9: 1060372.8 | Q9: 624815.84 | R9: 825769.74 | S9: 774024.13 | T9: 647730.57 | U9: 810994.28 | V9: 1009175.7 | W9: 902179.5 | X9: 853477.66 | Y9: 867849.17 | Z9: 1096312.4 | AA9: 920743.16 | AB9: 1071666 | AC9: 1113341.7 | AD9: 1325564.8 | AE9: 1117951.6
A10: Germany | B10: 93608.295 | C10: 99506.069 | D10: 110776.42 | E10: 140288.78 | F10: 186976.17 | G10: 289976.09 | H10: 375408.97 | I10: 300752.49 | J10: 294687.33 | K10: 212677.41 | L10: 362453.21 | M10: 399719.14 | N10: 449332.39 | O10: 820184.14 | P10: 1173072.3 | Q10: 525103.72 | R10: 768754.58 | S10: 831259.37 | T10: 728749.06 | U10: 939540.78 | V10: 1249522.5 | W10: 1180321.3 | X10: 1129649.3 | Y10: 1124478 | Z10: 1445552.3 | AA10: 1120312.7 | AB10: 1320899.3 | AC10: 1438562.5 | AD10: 1493735.2 | AE10: 1093135.9
A11: Greece | B11: 1450.9923 | C11: 2111.8727 | D11: 2917.6321 | E11: 4368.4294 | F11: 5625.004 | G11: 12001 | H11: 15210.649 | I11: 9584.15 | J11: 7711.375 | K11: 8425.2558 | L11: 16139.877 | M11: 28386.164 | N11: 37962.746 | O11: 60247.482 | P11: 93547.539 | Q11: 23892.706 | R11: 28114.75 | S11: 17106.032 | T11: 7480.0359 | U11: 10391.594 | V11: 13300.04 | W11: 16945.194 | X11: 16539.53 | Y11: 14755.292 | Z11: 19074.867 | AA11: 13103.38 | AB11: 18916.933 | AC11: 15289.666 | AD11: 21970.175 | AE11: 25219.757
A12: Iceland | B12: 0.46433676 | C12: 0.60383708 | D12: 1.0280769 | E12: 2.4370003 | F12: 1.7292005 | G12: 6.4168631 | H12: 60.372451 | I12: 30.747258 | J12: 117.82419 | K12: 236.41102 | L12: 292.97084 | M12: 781.25819 | N12: 3722.007 | O12: 4992.3109 | P12: 5845.384 | Q12: 103.66562 | R12: 493.85108 | S12: 465.96262 | T12: 465.21881 | U12: 463.98946 | V12: 590.72263 | W12: 599.49567 | X12: 713.96713 | Y12: 802.62365 | Z12: 1223.4821 | AA12: 1397.6962 | AB12: 2652.1883 | AC12: 2936.1371 | AD12: 3035.6496 | AE12: 2069.3185
A13: Ireland | B13: 16319.975 | C13: 20612.313 | D13: 30857.853 | E13: 44596.626 | F13: 63195.043 | G13: 109688.5 | H13: 160645.59 | I13: 217502.51 | J13: 279224.92 | K13: 343771.2 | L13: 481711.99 | M13: 613830.36 | N13: 712329.99 | O13: 950794.98 | P13: 1155092.1 | Q13: 889190.53 | R13: 1177526.3 | S13: 1407712.1 | T13: 1482030.5 | U13: 1771677.1 | V13: 2092944.2 | W13: 2351774.8 | X13: 2518358 | Y13: 2582621.9 | Z13: 3244308 | AA13: 3122831.8 | AB13: 3816112.3 | AC13: 4479826.7 | AD13: 5191368.4 | AE13: 4279407.2
... A26: United States | B26: 373521 | C26: 397720 | D26: 549513 | E26: 672397 | F26: 952893 | G26: 1250342 | H26: 1611534 | I26: 1643205 | J26: 1572681 | K26: 1335792 | L26: 1839509 | M26: 2123259 | N26: 2304013 | O26: 2791893 | P26: 3231651 | Q26: 2132433 | R26: 2917681 | S26: 3545769 | T26: 3841901 | U26: 4545361 | V26: 5864600 | W26: 6642507 | X26: 6209080 | Y26: 6570218 | Z26: 7941551 | AA26: 7539222 | AB26: 9296241 | AC26: 11834628 | AD26: 15250615 | AE26: 12054191

Sheet Portfolio debt liabilities 
A1: Country | K1: Portfolio debt liabilities
A2: Year | B2: 1993 | C2: 1994 | D2: 1995 | E2: 1996 | F2: 1997 | G2: 1998 | H2: 1999 | I2: 2000 | J2: 2001 | K2: 2002 | L2: 2003 | M2: 2004 | N2: 2005 | O2: 2006 | P2: 2007 | Q2: 2008 | R2: 2009 | S2: 2010 | T2: 2011 | U2: 2012 | V2: 2013 | W2: 2014 | X2: 2015 | Y2: 2016 | Z2: 2017 | AA2: 2018 | AB2: 2019 | AC2: 2020 | AD2: 2021 | AE2: 2022
A3: Australia | B3: 147173.48 | C3: 161939.72 | D3: 174379.07 | E3: 204596.58 | F3: 191238.95 | G3: 194006.66 | H3: 222339.6 | I3: 223861.78 | J3: 224252.53 | K3: 270665.59 | L3: 376270.72 | M3: 450550.29 | N3: 501922.43 | O3: 634968.86 | P3: 765498.08 | Q3: 707495.77 | R3: 913179.7 | S3: 1037250 | T3: 1156910.4 | U3: 1261043.5 | V3: 1208994.5 | W3: 1219123.2 | X3: 1223585.4 | Y3: 1214377.4 | Z3: 1346782.5 | AA3: 1308063 | AB3: 1344741.1 | AC3: 1468345.1 | AD3: 1444447.4 | AE3: 1351468.5
A4: Austria | B4: 118857.48 | C4: 137055.98 | D4: 165402.94 | E4: 162097.88 | F4: 163791.96 | G4: 197339.37 | H4: 224503 | I4: 248417.82 | J4: 265346.57 | K4: 319153.43 | L4: 400343.18 | M4: 485674.19 | N4: 500212.47 | O4: 624960.65 | P4: 747422.26 | Q4: 772436.86 | R4: 761452.89 | S4: 729423.81 | T4: 743674.47 | U4: 768445.7 | V4: 768067.53 | W4: 686215.36 | X4: 598311.45 | Y4: 569802.59 | Z4: 629274.9 | AA4: 609832.77 | AB4: 620302.47 | AC4: 700197.91 | AD4: 674458.4 | AE4: 628326.36
A5: Belgium | B5: 335809.14 | C5: 380700.53 | D5: 431282.52 | E5: 407175.97 | F5: 386825.66 | G5: 404457.41 | H5: 419383.29 | I5: 401770.78 | J5: 430202.15 | K5: 541953.55 | L5: 731850.29 | M5: 873387.04 | N5: 913670.45 | O5: 1086741.4 | P5: 1430108.2 | Q5: 1342478.4 | R5: 1232074.2 | S5: 1093340.1 | T5: 1080121.6 | U5: 1046867.5 | V5: 953359.07 | W5: 927021.34 | X5: 841077.24 | Y5: 876181.32 | Z5: 973628.73 | AA5: 906334.38 | AB5: 974160.5 | AC5: 1103761 | AD5: 1077107.5 | AE5: 1023643.8
A6: Canada | B6: 386955.37 | C6: 387114.01 | D6: 430301.62 | E6: 449359.52 | F6: 475019.64 | G6: 487914.94 | H6: 457978.91 | I6: 433413.93 | J6: 457379.65 | K6: 497447.87 | L6: 552387.18 | M6: 577851.08 | N6: 614835 | O6: 670224.15 | P6: 786355.31 | Q6: 768266.55 | R6: 920332.93 | S6: 1050238.6 | T6: 1169459.8 | U6: 1377073.6 | V6: 1359122.7 | W6: 1439510.5 | X6: 1443574.8 | Y6: 1570779.2 | Z6: 1789345.4 | AA6: 1790654 | AB6: 2120097.4 | AC6: 2378070.8 | AD6: 2534475.3 | AE6: 2577028.3
A7: Denmark | B7: 137565.72 | C7: 127172.18 | D7: 139104.68 | E7: 153339.88 | F7: 155090.44 | G7: 181801.68 | H7: 171396.22 | I7: 166439.14 | J7: 169667.15 | K7: 208159.88 | L7: 270088.86 | M7: 317566.74 | N7: 322166.27 | O7: 402691.1 | P7: 514820.71 | Q7: 529902.36 | R7: 548763.76 | S7: 547996.2 | T7: 521511.79 | U7: 532762.47 | V7: 556090.25 | W7: 485771.59 | X7: 422513.42 | Y7: 424282.75 | Z7: 490382.61 | AA7: 436956.78 | AB7: 436950.07 | AC7: 531546.73 | AD7: 492469.89 | AE7: 400077.65
A8: Finland | B8: 77732.34 | C8: 89099.561 | D8: 88012.777 | E8: 85473.384 | F8: 80344.719 | G8: 89920.888 | H8: 84900.702 | I8: 99527.953 | J8: 108350.97 | K8: 129999.37 | L8: 156084.9 | M8: 192416.4 | N8: 182828.62 | O8: 227433.08 | P8: 265105.66 | Q8: 271289.54 | R8: 349006.53 | S8: 391286.85 | T8: 472948.91 | U8: 539098.43 | V8: 531101.46 | W8: 489693.23 | X8: 418808.79 | Y8: 394918.59 | Z8: 422543.98 | AA8: 524487.7 | AB8: 537026.99 | AC8: 581348.63 | AD8: 518267.6 | AE8: 540116.7
A9: France | B9: 752186.34 | C9: 804545.02 | D9: 925156.23 | E9: 887250.72 | F9: 890987.92 | G9: 991271.64 | H9: 993164.71 | I9: 1091528.4 | J9: 1257677.4 | K9: 1578943.4 | L9: 2109505.9 | M9: 2630142.3 | N9: 2818924.4 | O9: 3528559.3 | P9: 4547056.4 | Q9: 4599079.9 | R9: 4946622.3 | S9: 4963036.3 | T9: 4747328.5 | U9: 5010509.8 | V9: 5143339 | W9: 5002149.4 | X9: 4582126.1 | Y9: 4571702.7 | Z9: 5317640.6 | AA9: 5533852.1 | AB9: 5931550.2 | AC9: 7009545.9 | AD9: 6795912.6 | AE9: 6341523.5
A10: Germany | B10: 916600.2 | C10: 1053139.6 | D10: 1324221.1 | E10: 1369863 | F10: 1287510 | G10: 1659584 | H10: 1740810.2 | I10: 1864379.9 | J10: 1932322.1 | K10: 2482504.3 | L10: 3043576.8 | M10: 3534308.2 | N10: 3396501.3 | O10: 3971704.6 | P10: 4827264.3 | Q10: 4839972.2 | R10: 4809463.3 | S10: 4926205.6 | T10: 5030998.5 | U10: 5180482 | V10: 4907931.6 | W10: 4620272.6 | X10: 4179863.6 | Y10: 4205936.5 | Z10: 4744284.4 | AA10: 4650815.8 | AB10: 4677889.3 | AC10: 5583511.2 | AD10: 5737884.8 | AE10: 5243540
A11: Greece | B11: 40960.865 | C11: 44380.865 | D11: 50302.865 | E11: 52411.865 | F11: 60011.865 | G11: 66599.792 | H11: 72210.11 | I11: 84761.092 | J11: 98240.849 | K11: 144981.97 | L11: 204482.13 | M11: 252918.89 | N11: 263937.17 | O11: 331608.16 | P11: 452431.19 | Q11: 504322.29 | R11: 593521.98 | S11: 548942.98 | T11: 495091.91 | U11: 588007.61 | V11: 579501.54 | W11: 505724.72 | X11: 471810.49 | Y11: 445178.05 | Z11: 474556.56 | AA11: 466713.17 | AB11: 493405.03 | AC11: 596584.43 | AD11: 619027.41 | AE11: 575132.5
A12: Iceland | B12: 4026.2576 | C12: 4085.5292 | D12: 4264.7719 | E12: 4431.6684 | F12: 4607.3989 | G12: 5838.3524 | H12: 6767.0839 | I12: 8518.4042 | J12: 9061.8747 | K12: 11083.763 | L12: 16041.611 | M12: 26534.789 | N12: 45348.762 | O12: 70498.688 | P12: 110500.97 | Q12: 112314.5 | R12: 109543.72 | S12: 109272.9 | T12: 99141.31 | U12: 91438.205 | V12: 95556.3 | W12: 85911.511 | X12: 21593.307 | Y12: 15703.623 | Z12: 15994.855 | AA12: 15546.191 | AB12: 14674.438 | AC12: 15356.293 | AD12: 17049.842 | AE12: 16432.83
A13: Ireland | B13: 55185.759 | C13: 61251.294 | D13: 95826.262 | E13: 123152.07 | F13: 151112.16 | G13: 228820.68 | H13: 292234.12 | I13: 296082.31 | J13: 348848.01 | K13: 470206.8 | L13: 695414.11 | M13: 972670.16 | N13: 1152137.2 | O13: 1554107.4 | P13: 1995333.9 | Q13: 2070755.8 | R13: 2048872.9 | S13: 1806078.4 | T13: 1865128.4 | U13: 1829612.1 | V13: 1892522 | W13: 1815826.8 | X13: 1715826.2 | Y13: 1636778.6 | Z13: 1869634.8 | AA13: 1971534.1 | AB13: 2186115.6 | AC13: 2526013.7 | AD13: 2594879.8 | AE13: 2415595.5
... A26: United States | B26: 2071273.8 | C26: 2269873.6 | D26: 2686887.1 | E26: 3077629.3 | F26: 3577050.7 | G26: 3783522.7 | H26: 3992218.7 | I26: 4511576.6 | J26: 5092559.4 | K26: 5857966 | L26: 6311376.6 | M26: 7727686 | N26: 8551594.7 | O26: 10494677 | P26: 12130246 | Q26: 12227230 | R26: 12154330 | S26: 13092822 | T26: 13992593 | U26: 14310394 | V26: 14894342 | W26: 15640128 | X26: 15565024 | Y26: 15917747 | Z26: 17112817 | AA26: 17562291 | AB26: 18990397 | AC26: 20481300 | AD26: 21710927 | AE26: 21013368

Sheet Market Cap
A1: Country | K1: Portfolio debt liabilities
A2: Year | B2: 1993 | C2: 1994 | D2: 1995 | E2: 1996 | F2: 1997 | G2: 1998 | H2: 1999 | I2: 2000 | J2: 2001 | K2: 2002 | L2: 2003 | M2: 2004 | N2: 2005 | O2: 2006 | P2: 2007 | Q2: 2008 | R2: 2009 | S2: 2010 | T2: 2011 | U2: 2012 | V2: 2013 | W2: 2014 | X2: 2015 | Y2: 2016 | Z2: 2017 | AA2: 2018 | AB2: 2019 | AC2: 2020 | AD2: 2021 | AE2: 2022
A3: Australia | B3: 204462770000 | C3: 218865190000 | D3: 245218330000 | E3: 312477330000 | F3: 295765570000 | G3: 328928480000 | H3: 427835360000 | I3: 372794350000 | J3: 375130790000 | K3: 380087000000 | L3: 585529690000 | M3: 776402760000 | N3: 804014820000 | O3: 1095857960000 | P3: 1298315040000 | Q3: 683871560000 | R3: 1261909340000 | S3: 1454490570000 | T3: 1198187410000 | U3: 1386873960000 | V3: 1365958130000 | W3: 1288708340000 | X3: 1187083450000 | Y3: 1.2684935e+12 | Z3: 1508462800000 | AA3: 1262800270000 | AB3: 1487598500000 | AC3: 1720556180000 | AD3: 1887400790000 | AE3: 1679171930000
A4: Austria | B4: 26238140000 | C4: 28819770000 | D4: 30617340000 | E4: 31914600000 | F4: 36820060000 | G4: 2600180000 | H4: 3.302295e+10 | I4: 29935220000 | J4: 25204350000 | K4: 3.357813e+10 | L4: 56522450000 | M4: 87776270000 | N4: 126251470000 | O4: 192770310000 | P4: 236448390000 | Q4: 76288700000 | R4: 114076070000 | S4: 126031960000 | T4: 85269520000 | U4: 106036780000 | V4: 117671410000 | W4: 96790330000 | X4: 96079380000 | Y4: 1.2097673e+11 | Z4: 150645990000 | AA4: 116802000000 | AB4: 133098220000 | AC4: 132083250000 | AD4: 162888880000 | AE4: 123048000000
A5: Belgium | B5: 77975730000 | C5: 84124970000 | D5: 101422290000 | E5: 118801970000 | F5: 136934280000 | G5: 244037800000 | H5: 184135510000 | I5: 182480520000 | J5: 165843000000 | K5: 127556560000 | L5: 173552620000 | M5: 2.7324742e+11 | N5: 288481060000 | O5: 396167930000 | P5: 385552940000 | Q5: 167218340000 | R5: 259768580000 | S5: 2.6872629e+11 | T5: 229320850000 | U5: 299517140000 | V5: 374325590000 | W5: 378525790000 | X5: 414556380000 | Y5: 3.7814428e+11 | Z5: 4.3779352e+11 | AA5: 3.2109354e+11 | AB5: .. | AC5: .. | AD5: .. | AE5: ..
A6: Canada | B6: 595516360000 | C6: 575716370000 | D6: 671742800000 | E6: 879797610000 | F6: 1010507310000 | G6: 1081927730000 | H6: 1448278090000 | I6: 770841540000 | J6: 615265930000 | K6: 888677700000 | L6: 910230610000 | M6: 1177517940000 | N6: 1482184560000 | O6: 1700708090000 | P6: 2186550150000 | Q6: 1033651810000 | R6: 1677431720000 | S6: 2.1711948e+12 | T6: 1912871970000 | U6: 2059973580000 | V6: 2113821770000 | W6: 2095420680000 | X6: 1593399300000 | Y6: 1.9935227e+12 | Z6: 2367059920000 | AA6: 1937902710000 | AB6: 2409098540000 | AC6: 2641454670000 | AD6: 3264137360000 | AE6: 2744719700000
A7: Denmark | B7: 39933390000 | C7: 47003330000 | D7: 56221940000 | E7: 71079200000 | F7: 93772820000 | G7: 98875480000 | H7: 97452590000 | I7: 111818640000 | J7: 85145500000 | K7: 76749870000 | L7: 121640960000 | M7: 151349870000 | N7: .. | O7: .. | P7: .. | Q7: .. | R7: .. | S7: .. | T7: .. | U7: .. | V7: .. | W7: .. | X7: .. | Y7: .. | Z7: .. | AA7: .. | AB7: .. | AC7: .. | AD7: .. | AE7: ..
A8: Finland | B8: 23524610000 | C8: 38230500000 | D8: 28918430000 | E8: 41555780000 | F8: 50653590000 | G8: 96718280000 | H8: 40804170000 | I8: 33146100000 | J8: 20391530000 | K8: 15277460000 | L8: 18763320000 | M8: 20344330000 | N8: .. | O8: .. | P8: .. | Q8: .. | R8: .. | S8: .. | T8: .. | U8: .. | V8: .. | W8: .. | X8: .. | Y8: .. | Z8: .. | AA8: .. | AB8: .. | AC8: .. | AD8: .. | AE8: ..
A9: France | B9: 455990150000 | C9: 452520780000 | D9: 499943560000 | E9: 585916300000 | F9: 674404750000 | G9: 151150690000 | H9: 1502951790000 | I9: 1446634120000 | J9: 1174663000000 | K9: 967015060000 | L9: 1355925340000 | M9: 1559109680000 | N9: 1758513210000 | O9: 2428251770000 | P9: 2740341210000 | Q9: 1472406870000 | R9: 1946185140000 | S9: 1911515390000 | T9: 1553956950000 | U9: 1808188710000 | V9: 2301085210000 | W9: 2085895800000 | X9: 2088317310000 | Y9: 2.1590466e+12 | Z9: 2.7493146e+12 | AA9: 2.3659502e+12 | AB9: .. | AC9: .. | AD9: .. | AE9: ..
A10: Germany | B10: 441696230000 | C10: 499191940000 | D10: 577373720000 | E10: 664783310000 | F10: 825232750000 | G10: 1094252520000 | H10: 1432166980000 | I10: 1270243170000 | J10: 1071748730000 | K10: 686013540000 | L10: 1079026240000 | M10: 1194516790000 | N10: 1202136280000 | O10: 1637609770000 | P10: 2.1051978e+12 | Q10: 1110579630000 | R10: 1292355310000 | S10: 1429719050000 | T10: 1184500160000 | U10: 1486314810000 | V10: 1936106260000 | W10: 1738539060000 | X10: 1715800490000 | Y10: 1.7160415e+12 | Z10: 2262222570000 | AA10: 1755172790000 | AB10: 2098173930000 | AC10: 2284108840000 | AD10: 2503045830000 | AE10: 1889663940000
A11: Greece | B11: .. | C11: .. | D11: .. | E11: .. | F11: .. | G11: .. | H11: .. | I11: .. | J11: 84752030000 | K11: 6.706146e+10 | L11: 106643670000 | M11: 125241630000 | N11: 145120740000 | O11: 200696040000 | P11: 264960820000 | Q11: 90200000000 | R11: 112632400000 | S11: 67586420000 | T11: 33778890000 | U11: 44876550000 | V11: 82594240000 | W11: 55154270000 | X11: 42079580000 | Y11: 3.7163049e+10 | Z11: 50605060000 | AA11: 38370850000 | AB11: 53653980000 | AC11: 50986890000 | AD11: 59242410000 | AE11: 59035280000
A12: Iceland | B12: .. | C12: .. | D12: .. | E12: .. | F12: .. | G12: .. | H12: .. | I12: .. | J12: .. | K12: .. | L12: .. | M12: .. | N12: .. | O12: .. | P12: .. | Q12: .. | R12: .. | S12: .. | T12: .. | U12: .. | V12: .. | W12: .. | X12: .. | Y12: .. | Z12: .. | AA12: .. | AB12: .. | AC12: .. | AD12: .. | AE12: ..
A13: Ireland | B13: .. | C13: .. | D13: .. | E13: .. | F13: 48902510000 | G13: 69676460000 | H13: 68773180000 | I13: 81882450000 | J13: 75297840000 | K13: 59937500000 | L13: 85070380000 | M13: 114085430000 | N13: 114086160000 | O13: 163269490000 | P13: 143905260000 | Q13: 49489910000 | R13: 61291120000 | S13: 60368310000 | T13: 108393170000 | U13: 108989160000 | V13: 170122680000 | W13: 143465830000 | X13: 128008850000 | Y13: 1.1982859e+11 | Z13: 146554130000 | AA13: 110154370000 | AB13: .. | AC13: .. | AD13: .. | AE13: ..
A14: Italy | B14: 145299650000 | C14: 185970720000 | D14: 209522520000 | E14: 256595340000 | F14: 344664970000 | G14: 294240000 | H14: 728240350000 | I14: 768363350000 | J14: 527467280000 | K14: 477075420000 | L14: 614841570000 | M14: 789562620000 | N14: 798072870000 | O14: 1026504210000 | P14: 1.0725347e+12 | Q14: 522087790000 | R14: 655848250000 | S14: 5.3505893e+11 | T14: 431486430000 | U14: 481827290000 | V14: 615462310000 | W14: 587312440000 | X14: .. | Y14: .. | Z14: .. | AA14: .. | AB14: .. | AC14: .. | AD14: .. | AE14: ..
A15: Japan | B15: 2906298700000 | C15: 3592193910000 | D15: 3545306510000 | E15: 3019733730000 | F15: 2085370340000 | G15: 2439548790000 | H15: 4455348090000 | I15: 3157221780000 | J15: 2264527900000 | K15: 2069299120000 | L15: 2953098300000 | M15: 3557674430000 | N15: 4572901030000 | O15: 4614068830000 | P15: 4.3309219e+12 | Q15: 3115803730000 | R15: 3306082050000 | S15: 3827774200000 | T15: 3325387760000 | U15: 3478831520000 | V15: 4543169140000 | W15: 4377994370000 | X15: 4894919120000 | Y15: 4.9552997e+12 | Z15: 6222825210000 | AA15: 5296811100000 | AB15: 6191073290000 | AC15: 6718219550000 | AD15: 6544303490000 | AE15: 5380475460000
A16: Mexico | B16: 200865240000 | C16: 130245850000 | D16: 90693960000 | E16: 106770460000 | F16: 156595010000 | G16: 91745800000 | H16: 154043880000 | I16: 125203830000 | J16: 126258380000 | K16: 103941150000 | L16: 122532960000 | M16: 171401990000 | N16: 239127950000 | O16: 348345130000 | P16: 397724640000 | Q16: 234054920000 | R16: 352045440000 | S16: 454345220000 | T16: 408689830000 | U16: 5.2505668e+11 | V16: 526015640000 | W16: 480245320000 | X16: 402253280000 | Y16: 3.5080955e+11 | Z16: 417020520000 | AA16: 385051430000 | AB16: 413618820000 | AC16: 399616700000 | AD16: 459707620000 | AE16: 454370430000
A17: Netherlands | B17: 181754190000 | C17: 223999880000 | D17: 286651490000 | E17: 375357820000 | F17: 468630690000 | G17: 603182200000 | H17: 694055330000 | I17: 640456300000 | J17: 503022880000 | K17: 401267710000 | L17: 488647360000 | M17: 5.3866369e+11 | N17: 592835610000 | O17: 779542640000 | P17: 956157630000 | Q17: 388720840000 | R17: 559195310000 | S17: 661099200000 | T17: 594636520000 | U17: 650811190000 | V17: 817840280000 | W17: 786573520000 | X17: 728485580000 | Y17: 8.0572444e+11 | Z17: 1.1001054e+12 | AA17: .. | AB17: .. | AC17: .. | AD17: .. | AE17: ..
A18: New Zealand | B18: 25620870000 | C18: 27117660000 | D18: 31373000000 | E18: 38290580000 | F18: 30509230000 | G18: 24783940000 | H18: 28351500000 | I18: 18613210000 | J18: 17821780000 | K18: 21761620000 | L18: 3.304976e+10 | M18: 43731330000 | N18: 40592460000 | O18: 44816540000 | P18: 47485600000 | Q18: 24209610000 | R18: 35506850000 | S18: .. | T18: .. | U18: 52870100000 | V18: 65961560000 | W18: 74415690000 | X18: 74350500000 | Y18: 8.0048459e+10 | Z18: 94691280000 | AA18: 86132630000 | AB18: 107879780000 | AC18: 132198460000 | AD18: 122933780000 | AE18: 97545700000
A19: Norway | B19: 27371140000 | C19: 36459340000 | D19: 44586980000 | E19: 56877690000 | F19: 66509410000 | G19: 46420920000 | H19: 63699920000 | I19: 65774110000 | J19: 69465400000 | K19: 64169760000 | L19: 95919910000 | M19: 141429860000 | N19: 191078560000 | O19: 280851340000 | P19: 354919790000 | Q19: 145906340000 | R19: 227233230000 | S19: 295288300000 | T19: 220936390000 | U19: 242764880000 | V19: 2.653771e+11 | W19: 219369670000 | X19: 193895750000 | Y19: 2.3125719e+11 | Z19: 287192200000 | AA19: 267382190000 | AB19: 295548630000 | AC19: .. | AD19: .. | AE19: ..
A20: Portugal | B20: .. | C20: .. | D20: .. | E20: .. | F20: 38953480000 | G20: 62954000000 | H20: 6.814774e+10 | I20: 60680690000 | J20: 46337810000 | K20: 42845350000 | L20: 58284740000 | M20: 70240380000 | N20: 6.69734e+10 | O20: 104187320000 | P20: 1.3223854e+11 | Q20: 68876020000 | R20: 98247200000 | S20: 81996700000 | T20: 61689890000 | U20: 65519040000 | V20: 79177900000 | W20: 57774190000 | X20: 59837190000 | Y20: 5.7255224e+10 | Z20: 7.5589629e+10 | AA20: 6.1933605e+10 | AB20: .. | AC20: .. | AD20: .. | AE20: ..
A21: Spain | B21: 118667810000 | C21: 154984140000 | D21: 190570530000 | E21: 241028150000 | F21: 290382930000 | G21: 402162640000 | H21: 430900070000 | I21: 504219320000 | J21: 468203190000 | K21: 461559380000 | L21: 726243370000 | M21: 940672880000 | N21: 959910390000 | O21: 1322915300000 | P21: 1799833980000 | Q21: 948352290000 | R21: 1434540470000 | S21: 1171624980000 | T21: 1030987550000 | U21: 995088450000 | V21: 1116561030000 | W21: 992913610000 | X21: 787192290000 | Y21: 7.0455133e+11 | Z21: 888837580000 | AA21: 723690970000 | AB21: 797285840000 | AC21: 759174660000 | AD21: 775649630000 | AE21: 665497680000
A22: Sweden | B22: 100510120000 | C22: 119259980000 | D22: 172550320000 | E22: 240382280000 | F22: 264710130000 | G22: 278707220000 | H22: 373277650000 | I22: 328339040000 | J22: 236514390000 | K22: 179117370000 | L22: 289877140000 | M22: .. | N22: .. | O22: .. | P22: .. | Q22: .. | R22: .. | S22: .. | T22: .. | U22: .. | V22: .. | W22: .. | X22: .. | Y22: .. | Z22: .. | AA22: .. | AB22: .. | AC22: .. | AD22: .. | AE22: ..
A23: Switzerland | B23: 2.7087923e+11 | C23: 284976880000 | D23: 398102020000 | E23: 400284680000 | F23: 575339370000 | G23: 689199130000 | H23: 678232020000 | I23: 792315950000 | J23: 527355900000 | K23: 612667140000 | L23: 727102780000 | M23: 829098070000 | N23: 938697660000 | O23: 1212534300000 | P23: 1274656700000 | Q23: 880334430000 | R23: 1064686540000 | S23: 1229356540000 | T23: 1.0895194e+12 | U23: 1233438940000 | V23: 1540699830000 | W23: 1495314200000 | X23: 1519323460000 | Y23: 1.4033556e+12 | Z23: 1686497070000 | AA23: 1441160480000 | AB23: 1834453260000 | AC23: 2001602870000 | AD23: 2327707010000 | AE23: 1830524610000
A24: Turkey | B24: 36612690000 | C24: 21605060000 | D24: 20771720000 | E24: 30311800000 | F24: 61095030000 | G24: 3.364559e+10 | H24: 112715840000 | I24: 69710920000 | J24: 48387990000 | K24: 36043970000 | L24: 68379000000 | M24: 98298000000 | N24: 159997200000 | O24: 160875110000 | P24: 284530840000 | Q24: 117584350000 | R24: 231676450000 | S24: 302443140000 | T24: 197074460000 | U24: 315197530000 | V24: 195745520000 | W24: 219762560000 | X24: 188861890000 | Y24: 1.7176494e+11 | Z24: 227511820000 | AA24: 149263560000 | AB24: 184966060000 | AC24: 237473620000 | AD24: 138395240000 | AE24: 330011020000
A25: United Kingdom | B25: 1150283390000 | C25: 1143329850000 | D25: 1329936350000 | E25: 1711228010000 | F25: 2068246130000 | G25: 2297650970000 | H25: 2954815470000 | I25: 2576991340000 | J25: 2.1495008e+12 | K25: 1856194400000 | L25: 2425822000000 | M25: 2815928030000 | N25: 3058182420000 | O25: 3781358500000 | P25: 3846461880000 | Q25: 1868152970000 | R25: 2796444320000 | S25: 2686880880000 | T25: 2932240870000 | U25: 3291640120000 | V25: 3946884730000 | W25: 3570893500000 | X25: .. | Y25: .. | Z25: .. | AA25: .. | AB25: .. | AC25: .. | AD25: 3799459240000 | AE25: 3095983430000
A26: United States | B26: 5251079630000 | C26: 5137739860000 | D26: 6952026000000 | E26: 8480497000000 | F26: 10770143000000 | G26: 12922580000000 | H26: 14777387400000 | I26: 15107751000000 | J26: 13983666000000 | K26: 11054430000000 | L26: 14266265650000 | M26: 16323726330000 | N26: 1.7000864e+13 | O26: 19568972500000 | P26: 19922279820000 | Q26: 11590277780000 | R26: 15077285740000 | S26: 17283451680000 | T26: 15640707040000 | U26: 18668333210000 | V26: 24034853520000 | W26: 26330589190000 | X26: 25067539600000 | Y26: 27352200720000 | Z26: 32120702650000 | AA26: 30436313050000 | AB26: 34085727370000 | AC26: 41569861770000 | AD26: 48548538120000 | AE26: 40297980320000
B29: =B3/1000000 -> 204462.77

Sheet Domestic debt
A1: Country | K1: Domestic Debt
A2: Year | B2: 1993 | C2: 1994 | D2: 1995 | E2: 1996 | F2: 1997 | G2: 1998 | H2: 1999 | I2: 2000 | J2: 2001 | K2: 2002 | L2: 2003 | M2: 2004 | N2: 2005 | O2: 2006 | P2: 2007 | Q2: 2008 | R2: 2009 | S2: 2010 | T2: 2011
A3: Australia | B3: 144.448 | C3: 224.785 | D3: 218.98 | E3: 247.714 | F3: 210.929 | G3: 211.066 | H3: 253.914 | I3: 215.424 | J3: 208.615 | K3: 250.741 | L3: 360.34 | M3: 418.556 | N3: 433.413 | O3: 530.245 | P3: 782.427 | Q3: 618.603 | R3: 845.058 | S3: 965.073 | T3: 1023.401
A4: Austria | B4: 98.831 | C4: 120.721 | D4: 141.397 | E4: 138.987 | F4: 132.208 | G4: 142.202 | H4: 141.72 | I4: 140.47 | J4: 136.382 | K4: 167.09 | L4: 203.342 | M4: 226.421 | N4: 208.789 | O4: 251.11 | P4: 314.823 | Q4: 328.312 | R4: 364.73 | S4: 362.351 | T4: 335.447
A5: Belgium | B5: 310.486 | C5: 384.592 | D5: 435.528 | E5: 428.658 | F5: 374.26 | G5: 396.156 | H5: 333.446 | I5: 310.118 | J5: 283.74 | K5: 333.288 | L5: 379.434 | M5: 388.953 | N5: 318.849 | O5: 352.449 | P5: 418.525 | Q5: 477.777 | R5: 585.782 | S5: 548.414 | T5: 550.088
A6: Canada | B6: 539.315 | C6: 532.698 | D6: 581.024 | E6: 595.363 | F6: 603.82 | G6: 581.544 | H6: 661.669 | I6: 662.268 | J6: 636.237 | K6: 652.512 | L6: 812.893 | M6: 904.988 | N6: 978.209 | O6: 1033.861 | P6: 1208.721 | Q6: 1033.924 | R6: 1324.623 | S6: 1485.437 | T6: 1547.658
